Traceback (most recent call last):
  File "C:\Users\John\anaconda3\envs\cvr\lib\site-packages\jupyter_cache\executors\utils.py", line 56, in single_nb_execution
    record_timing=False,
  File "C:\Users\John\anaconda3\envs\cvr\lib\site-packages\nbclient\client.py", line 1085, in execute
    return NotebookClient(nb=nb, resources=resources, km=km, **kwargs).execute()
  File "C:\Users\John\anaconda3\envs\cvr\lib\site-packages\nbclient\util.py", line 84, in wrapped
    return just_run(coro(*args, **kwargs))
  File "C:\Users\John\anaconda3\envs\cvr\lib\site-packages\nbclient\util.py", line 62, in just_run
    return loop.run_until_complete(coro)
  File "C:\Users\John\anaconda3\envs\cvr\lib\asyncio\base_events.py", line 587, in run_until_complete
    return future.result()
  File "C:\Users\John\anaconda3\envs\cvr\lib\site-packages\nbclient\client.py", line 552, in async_execute
    cell, index, execution_count=self.code_cells_executed + 1
  File "C:\Users\John\anaconda3\envs\cvr\lib\site-packages\nbclient\client.py", line 846, in async_execute_cell
    self._check_raise_for_error(cell, exec_reply)
  File "C:\Users\John\anaconda3\envs\cvr\lib\site-packages\nbclient\client.py", line 748, in _check_raise_for_error
    raise CellExecutionError.from_cell_and_msg(cell, exec_reply_content)
nbclient.exceptions.CellExecutionError: An error occurred while executing the following cell:
------------------
# IMPORTS
from myst_nb import glue
import pandas as pd
from datetime import datetime
pd.set_option('display.width', 1000)
pd.options.display.float_format = '{:,.2f}'.format

from cvr.core.asset import AssetPassport
from cvr.core.pipeline import DataPipelineBuilder, PipelineConfig
from cvr.core.atelier import AtelierFabrique
from cvr.utils.config import CriteoConfig 
from cvr.core.dataset import Dataset, DatasetFactory, DatasetWriter, Download, Extract, DatasetReader
------------------

[1;31m---------------------------------------------------------------------------[0m
[1;31mModuleNotFoundError[0m                       Traceback (most recent call last)
[1;32m~\AppData\Local\Temp\ipykernel_10712\1074939191.py[0m in [0;36m<module>[1;34m[0m
[0;32m      6[0m [0mpd[0m[1;33m.[0m[0moptions[0m[1;33m.[0m[0mdisplay[0m[1;33m.[0m[0mfloat_format[0m [1;33m=[0m [1;34m'{:,.2f}'[0m[1;33m.[0m[0mformat[0m[1;33m[0m[1;33m[0m[0m
[0;32m      7[0m [1;33m[0m[0m
[1;32m----> 8[1;33m [1;32mfrom[0m [0mcvr[0m[1;33m.[0m[0mcore[0m[1;33m.[0m[0masset[0m [1;32mimport[0m [0mAssetPassport[0m[1;33m[0m[1;33m[0m[0m
[0m[0;32m      9[0m [1;32mfrom[0m [0mcvr[0m[1;33m.[0m[0mcore[0m[1;33m.[0m[0mpipeline[0m [1;32mimport[0m [0mDataPipelineBuilder[0m[1;33m,[0m [0mPipelineConfig[0m[1;33m[0m[1;33m[0m[0m
[0;32m     10[0m [1;32mfrom[0m [0mcvr[0m[1;33m.[0m[0mcore[0m[1;33m.[0m[0matelier[0m [1;32mimport[0m [0mAtelierFabrique[0m[1;33m[0m[1;33m[0m[0m

[1;31mModuleNotFoundError[0m: No module named 'cvr'
ModuleNotFoundError: No module named 'cvr'

